Traceback (most recent call last):
  File "chapter11.py", line 35, in <module>
    raise Exception('This is the error message.')
Exception: This is the error message.
